Workbook

Sheet Conflict - Environment - XCheck
A1: Date | B1: Conflict / Location | C1: Environmental damage | D1: Deliberate / Byproduct / Hybrid | E1: Why it is significant | F1: Source | G1: ISO | H1: Image | I1: URL | J1: Credit | K1: Conflict | L1: Year from | M1: Year to
A2: 2001–present | B2: Afghanistan | C2: Deforestation, wetland desiccation, falling water tables and wildlife loss | D2: Byproduct | E2: Decades of war weakened environmental governance and accelerated extraction of timber and other resources. UNEP found widespread loss of vegetation, erosion, declining water tables and wetlands. | F2: UNEP - UN Environment Programme | G2: AF | H2: 001 | K2: War in Afghanistan | L2: 2001
A3: 2003 | B3: Iraq War – Al-Mishraq sulphur fire | C3: Enormous sulphur-dioxide release | D3: Deliberate | E3: A sulphur plant near Mosul burned for almost a month, releasing roughly 21,000–23,000 tonnes of SO₂ per day at its peak. The plume travelled across several countries and damaged vegetation and human health. | F3: UNEP - UN Environment Programme | G3: IQ | H3: 002 | K3: Iraq War and insurgency | L3: 2003 | M3: 2003
A4: 2003 onward | B4: Iraq | C4: Industrial contamination, oil fires, military waste and toxic sites | D4: Hybrid | E4: UNEP identified several thousand potentially contaminated sites arising from military activity, damaged industry and post-war looting, including hazardous chemicals, oil, heavy metals and military scrap. | F4: UNEP - UN Environment Programme | G4: IQ | H4: 003 | K4: Iraq War and insurgency | L4: 2003
A5: 2000s–present | B5: Eastern DRC / Virunga | C5: Deforestation, charcoal extraction and poaching linked to armed groups | D5: Deliberate | E5: Armed groups have financed themselves through charcoal and natural-resource exploitation. Conflict has reduced conservation control and placed internationally important habitats under sustained pressure. | F5: UNESCO World Heritage Centre | G5: CD | H5: 004 | K5: Kivu / Ituri conflicts and M23 | L5: 2000
A6: 2003–present | B6: Darfur / Sudan | C6: Deforestation, land degradation and pressure on water/resources | D6: Byproduct | E6: Mass displacement and collapse of resource governance increased fuelwood extraction, grazing and degradation around settlements and camps. UNEP has identified a strong conflict–environment relationship in Sudan. | F6: WEDocs | G6: SD | H6: 005 | K6: Darfur conflict | L6: 2003
A7: 2006 | B7: Lebanon War – Jiyeh power station | C7: Mediterranean oil spill | D7: Deliberate | E7: Bombing of fuel tanks released about 12,000–15,000 tonnes of heavy fuel oil. More than 70 sites and roughly 150 km of Lebanese coastline were contaminated, with pollution reaching Syria. | F7: Ministry of Education Lebanon | G7: LB | H7: 006 | K7: Second Lebanon War | L7: 2006 | M7: 2006
A8: 2008–09 | B8: Gaza conflict | C8: Sewage pollution, asbestos-contaminated rubble and damaged infrastructure | D8: Byproduct | E8: UNEP documented conflict debris containing hazardous substances and sewage pollution of coastal waters, demonstrating how destruction of the built environment becomes an environmental problem long after combat stops. | F8: UNEP - UN Environment Programme | G8: PS | H8: 007 | K8: Gaza wars and Israeli–Palestinian conflict | L8: 2008 | M8: 2009
A9: 2011–present | B9: Syrian Civil War | C9: Oil pollution and improvised refining | D9: Deliberate | E9: Bombing and seizure of conventional refineries encouraged thousands of makeshift oil refineries. Satellite analysis identified around 5,800 installations at just five sites by 2016, contaminating air, soil, farmland and potentially groundwater. | F9: CEOBS | G9: SY | H9: 008 | K9: Syrian civil war | L9: 2011
A10: 2011–present | B10: Syria | C10: Urban rubble and destruction of water/sewage infrastructure | D10: Byproduct | E10: Aleppo alone was estimated to contain around 14.9 million tonnes of conflict debris; industrial areas and sewage, electricity and water systems were also extensively damaged. | F10: CEOBS | G10: SY | H10: 009 | K10: Syrian civil war | L10: 2011
A11: 2013–present | B11: South Sudan | C11: Oil-field pollution near sensitive wetlands | D11: Deliberate | E11: Conflict damaged oil infrastructure while weak regulation led to spills, fires and soil/water pollution in and around oil-producing landscapes connected to the Sudd, one of the world's largest wetlands. | F11: UNEP - UN Environment Programme | G11: SS | H11: 010 | K11: South Sudanese civil war | L11: 2013
A12: 2014–present | B12: Donbas, Ukraine | C12: Flooded coal mines and groundwater contamination | D12: Hybrid | E12: Fighting and abandonment of mines caused pumping systems to fail. Flooded mines create long-term risks of contaminated minewater migrating into groundwater and rivers. | F12: CEOBS | G12: UA | H12: 011 | K12: Russo-Ukrainian war | L12: 2014
A13: 2015–present | B13: Yemen | C13: Destruction of water and sanitation systems | D13: Byproduct | E13: Water infrastructure has repeatedly been damaged while electricity and maintenance systems collapsed. Waste disposal deterioration and sewage problems compounded one of the world's severest water crises. | F13: ICRC | G13: YE | H13: 012 | K13: Yemen civil war and Houthi conflict | L13: 2015
A14: 2016–17 | B14: Battle for Mosul / Qayyarah, Iraq | C14: Oil-well and sulphur fires | D14: Hybrid | E14: Retreating Islamic State forces ignited 19 oil wells and sulphur stocks. Toxic smoke covered large areas and more than 1,000 people required treatment for suffocation following the sulphur fire. | F14: UNEP - UN Environment Programme | G14: IQ | H14: 013 | K14: War against Islamic State (Iraq & Syria) | L14: 2016 | M14: 2017
A15: 2000s–2016+ | B15: Colombian armed conflict | C15: Illegal mining, mercury contamination and deforestation | D15: Deliberate | E15: Armed groups used mining and natural-resource extraction as revenue sources. UNEP identifies unregulated mining, illicit crops, deforestation and mercury use as important environmental consequences of the conflict economy. | F15: UNEP - UN Environment Programme | G15: CO | H15: 014 | K15: Colombian armed conflict | L15: 2000
A16: 2022 | B16: Nord Stream pipeline explosions | C16: Exceptional methane release | D16: Deliberate | E16: The pipeline ruptures released up to 485,000 tonnes of methane, which UNEP describes as the largest known human-caused methane release from a single event. It is best considered conflict-adjacent sabotage, however, rather than straightforward battlefield environmental damage. | F16: UNEP - UN Environment Programme | G16: DK,SE | H16: 015 | K16: Nord Stream pipeline sabotage | L16: 2022 | M16: 2022
A17: 2022–present | B17: Full-scale war in Ukraine | C17: Industrial, chemical, agricultural and ecological contamination | D17: Hybrid | E17: Fighting has affected oil depots, refineries, chemical plants, power stations, mines, sewage works, forests, protected areas and agricultural soils. UNEP describes the resulting situation as a multidimensional environmental crisis. | F17: UNEP - UN Environment Programme | G17: UA | H17: 016 | K17: Russo-Ukrainian war | L17: 2022
A18: 2022–present | B18: Ukraine | C18: Landmines, unexploded ordnance and military contamination | D18: Byproduct | E18: Vast areas of agricultural and natural land are contaminated with mines, explosives, propellants, metals and damaged military equipment, complicating farming, conservation and ecological recovery for decades. | F18: UNEP - UN Environment Programme | G18: UA | H18: 017 | K18: Russo-Ukrainian war | L18: 2022
A19: June 2023 | B19: Ukraine – Kakhovka Dam | C19: Catastrophic hydrological and ecological change | D19: Deliberate | E19: The breach flooded about 620 km², while the reservoir upstream disappeared across a much larger area. UNEP found hydrological, geomorphological, chemical and ecological impacts, including damage to protected habitats, some likely irreversible. | F19: UNEP - UN Environment Programme | G19: UA | H19: 018 | K19: Russo-Ukrainian war | L19: 2023 | M19: 2023
A20: 2023–25 | B20: Gaza war | C20: Extraordinary quantities of conflict rubble | D20: Byproduct | E20: By mid-2025 UNEP estimated more than 61 million tonnes of debris, some contaminated with asbestos, heavy metals, industrial chemicals and unexploded ordnance. | F20: UNEP - UN Environment Programme | G20: PS | H20: 019 | K20: Gaza wars and Israeli–Palestinian conflict | L20: 2023 | M20: 2025
A21: 2023–25 | B21: Gaza war | C21: Destruction of agricultural ecosystems | D21: Byproduct | E21: UNEP estimated losses of 97% of tree crops, 95% of shrubland and 82% of annual crops, alongside soil compaction, damaged water infrastructure and pollution risks to the coastal aquifer. | F21: UNEP - UN Environment Programme | G21: PS | H21: 020 | K21: Gaza wars and Israeli–Palestinian conflict | L21: 2023 | M21: 2025
A22: 2023–present | B22: Sudanese Civil War | C22: Oil refinery fires, industrial contamination and deforestation | D22: Deliberate | E22: Repeated fighting at the Al-Jaili refinery caused large fires and contamination; a January 2025 fire produced a smoke plume extending more than 300 km. Conflict-related fuel shortages have also contributed to vegetation loss through charcoal and fuelwood extraction. | F22: CEOBS | G22: SD | H22: 021 | K22: Sudanese civil war (RSF vs SAF) | L22: 2023
A23: February–March 2024 | B23: Red Sea conflict – MV Rubymar | C23: Oil/fuel pollution and fertiliser contamination risk | D23: Deliberate | E23: A Houthi missile strike ultimately sank the vessel with around 21,000 tonnes of ammonium phosphate sulphate fertiliser aboard. It had already produced a long fuel slick, while the cargo threatened coral ecosystems through nutrient pollution and oxygen depletion. | F23: Reuters | G23: YE | H23: 022 | K23: Yemen civil war and Houthi conflict | L23: 2024 | M23: 2024
A24: 2024–present | B24: Ukraine – fibre-optic FPV drones | C24: Kilometres of persistent plastic cabling deposited across landscapes | D24: Hybrid | E24: This is particularly interesting because it is a genuinely new form of conflict pollution. Individual drones can carry 5–20 km of cable, which is simply left across woodland, fields and waterways. Potential impacts include wildlife entanglement, microplastics, PFAS contamination and interference with agriculture and mine clearance. The ecological scale is not yet quantified, so it should be described as an emerging environmental threat, rather than equated with Kakhovka. | F24: CEOBS | G24: UA | H24: 023 | K24: Russo-Ukrainian war | L24: 2024
A25: 2026 | B25: Iran / wider Middle-East conflict | C25: Oil-facility fires and atmospheric pollution | D25: Deliberate | E25: UNEP has confirmed strikes on oil facilities, including around urban areas, producing large smoke plumes containing hazardous compounds. The conflict is still developing, so the eventual ecological scale cannot yet be assessed reliably. | G25: IR | H25: 024 | K25: 2026 Iran war | L25: 2026 | M25: 2026

Sheet Conflicts
A1: Conflict | B1: Years | C1: Countries involved (ISO) | D1: Notes | E1: Year from | F1: Year to
A2: War in Afghanistan | B2: 2001–2021 | C2: AF,PK,US | D2: US-led intervention against the Taliban; Pakistan border spillover | E2: 2001 | F2: 2021
A3: Iraq War and insurgency | B3: 2003–2011 | C3: IQ,IR,SY,US | D3: US-led invasion, occupation and insurgency | E3: 2003 | F3: 2011
A4: War against Islamic State (Iraq & Syria) | B4: 2014–2019 | C4: IQ,SY,IR,TR | D4: Anti-ISIS campaign; Iran and Turkey active | E4: 2014 | F4: 2019
A5: Syrian civil war | B5: 2011–2024 | C5: SY,IR,LB,IL,TR,RU | D5: Foreign involvement by Iran, Hezbollah, Turkey, Russia, Israel | E5: 2011 | F5: 2024
A6: Second Lebanon War | B6: 2006 | C6: IL,LB | D6: Israel–Hezbollah war | E6: 2006 | F6: 2006
A7: Gaza wars and Israeli–Palestinian conflict | B7: 2008–present | C7: IL,PS,LB,IR,YE | D7: Gaza wars 2008–09, 2014, 2023–; regional spillover | E7: 2008
A8: Israel–Hezbollah war 2023–24 | B8: 2023–2024 | C8: IL,LB,IR | D8: Cross-border war and 2024 Israeli invasion | E8: 2023 | F8: 2024
A9: 2026 Iran war | B9: 2026 | C9: IR,IL | D9: Strikes involving Iran and Israel; ongoing | E9: 2026 | F9: 2026
A10: Second Congo War | B10: 1998–2003 | C10: CD,RW,UG,BI,AO | D10: Regional war overlapping the early 2000s | E10: 1998 | F10: 2003
A11: Kivu / Ituri conflicts and M23 | B11: 2004–present | C11: CD,RW,UG,BI | D11: Eastern DRC armed groups and Rwanda-backed M23 | E11: 2004
A12: ADF and LRA insurgencies | B12: 2000s–present | C12: CD,UG,SS,CF | D12: Ugandan-origin rebel groups across the DRC/CAR border | E12: 2000
A13: Darfur conflict | B13: 2003–2020 | C13: SD,TD,CF | D13: Darfur war and Chad spillover | E13: 2003 | F13: 2020
A14: Second Sudanese civil war aftermath / South Kordofan & Blue Nile | B14: 2011–present | C14: SD,SS | D14: Insurgency along the Sudan–South Sudan border | E14: 2011
A15: Sudanese civil war (RSF vs SAF) | B15: 2023–present | C15: SD,TD,SS,LY | D15: Army–RSF war; regional supply lines | E15: 2023
A16: South Sudanese civil war | B16: 2013–2020 | C16: SS,UG,SD | D16: Intra-South Sudan war with Ugandan intervention | E16: 2013 | F16: 2020
A17: Eritrean–Ethiopian border war | B17: 1998–2000, tension to 2018 | C17: ER,ET | D17: Border war | E17: 1998 | F17: 2018
A18: Tigray war | B18: 2020–2022 | C18: ET,ER | D18: Ethiopia, Tigrayan forces and Eritrea | E18: 2020 | F18: 2022
A19: Oromia and Amhara insurgencies | B19: 2018–present | C19: ET | D19: Internal insurgencies | E19: 2018
A20: Somali civil war and al-Shabaab | B20: 2006–present | C20: SO,KE,ET,UG,DJ,US | D20: AMISOM/ATMIS and neighbouring states | E20: 2006
A21: Kashmir conflict | B21: 2000s–present | C21: IN,PK,CN | D21: India–Pakistan and India–China border tensions | E21: 2000
A22: Naxalite–Maoist insurgency | B22: 2000s–present | C22: IN | D22: Internal insurgency | E22: 2000
A23: Northeast India insurgencies / Manipur | B23: 2000s–present | C23: IN,MM | D23: Insurgencies across the Myanmar border | E23: 2000
A24: Myanmar internal conflict (Rohingya, Kachin, Karen) | B24: 2000s–2020 | C24: MM,BD | D24: Ethnic armed conflicts | E24: 2000 | F24: 2020
A25: Myanmar civil war | B25: 2021–present | C25: MM,CN,TH,IN | D25: Post-coup civil war | E25: 2021
A26: Boko Haram insurgency | B26: 2009–present | C26: NG,NE,TD,CM | D26: Lake Chad basin | E26: 2009
A27: Mali war and Sahel insurgency | B27: 2012–present | C27: ML,BF,NE,MR,DZ,CI,BJ,TG,SN,RU | D27: Jihadist insurgency; Russian Wagner/Africa Corps | E27: 2012
A28: Libyan conflicts | B28: 2011–present | C28: LY,EG,TR,RU | D28: Civil wars and foreign backers | E28: 2011
A29: Colombian armed conflict | B29: 2000s–2016 | C29: CO,VE,EC | D29: FARC/ELN conflict; Venezuelan and Ecuadorian border | E29: 2000 | F29: 2016
A30: Yemen civil war and Houthi conflict | B30: 2014–present | C30: YE,SA,IR,IL | D30: Saudi-led intervention; Red Sea attacks | E30: 2014
A31: Russo-Ukrainian war | B31: 2014–present | C31: UA,RU,BY | D31: Donbas war and full-scale invasion | E31: 2014
A32: Chechen wars and North Caucasus insurgency | B32: 1999–2017 | C32: RU | D32: Second Chechen War and insurgency | E32: 1999 | F32: 2017
A33: Russo-Georgian war | B33: 2008 | C33: GE,RU | D33: August 2008 war | E33: 2008 | F33: 2008
A34: Nagorno-Karabakh conflict | B34: 2020–2023 | C34: AM,AZ,TR | D34: Wars of 2020 and 2023 | E34: 2020 | F34: 2023
A35: Mexican drug war | B35: 2006–present | C35: MX,US | D35: Cartel violence | E35: 2006
A36: Insurgency in Southern Thailand | B36: 2004–present | C36: TH,MY | D36: Deep South insurgency | E36: 2004
A37: Insurgency in the Philippines (Moro and NPA) | B37: 2000s–present | C37: PH,MY | D37: Mindanao conflict and Communist insurgency | E37: 2000
A38: Papua conflict and Indonesian insurgencies | B38: 2000s–present | C38: ID,PG | D38: Aceh, Papua, Poso | E38: 2000
A39: Turkey–PKK conflict | B39: 1984–2025 | C39: TR,IQ,SY | D39: Kurdish insurgency | E39: 1984 | F39: 2025
A40: Iran–Pakistan and Baloch insurgencies | B40: 2000s–present | C40: IR,PK | D40: Balochistan | E40: 2000
...

Sheet Conflict Tiers
A1: ISO | B1: Tier (1 = one conflict, 2 = two, 3 = three or more) | C1: Conflicts listed in Conflicts sheet
A2: CD | B2: 3 | C2: =COUNTIF(Conflicts!$C$2:$C$73,"*"&A2&"*") -> 4
A3: ET | B3: 3 | C3: =COUNTIF(Conflicts!$C$2:$C$73,"*"&A3&"*") -> 4
A4: IL | B4: 3 | C4: =COUNTIF(Conflicts!$C$2:$C$73,"*"&A4&"*") -> 8
A5: IN | B5: 3 | C5: =COUNTIF(Conflicts!$C$2:$C$73,"*"&A5&"*") -> 7
A6: IQ | B6: 3 | C6: =COUNTIF(Conflicts!$C$2:$C$73,"*"&A6&"*") -> 3
A7: LB | B7: 3 | C7: =COUNTIF(Conflicts!$C$2:$C$73,"*"&A7&"*") -> 4
A8: MM | B8: 3 | C8: =COUNTIF(Conflicts!$C$2:$C$73,"*"&A8&"*") -> 3
A9: SD | B9: 3 | C9: =COUNTIF(Conflicts!$C$2:$C$73,"*"&A9&"*") -> 6
A10: SY | B10: 3 | C10: =COUNTIF(Conflicts!$C$2:$C$73,"*"&A10&"*") -> 4
A11: AF | B11: 2 | C11: =COUNTIF(Conflicts!$C$2:$C$73,"*"&A11&"*") -> 2
A12: CO | B12: 2 | C12: =COUNTIF(Conflicts!$C$2:$C$73,"*"&A12&"*") -> 2
A13: ER | B13: 2 | C13: =COUNTIF(Conflicts!$C$2:$C$73,"*"&A13&"*") -> 3
... A79: UZ | B79: 1 | C79: =COUNTIF(Conflicts!$C$2:$C$73,"*"&A79&"*") -> 1
